<?xml version="1.0"?>
<robot name="racecar" xmlns:xacro="http://www.ros.org/wiki/xacro">

<!--material-->
<material name="black">
  <color rgba="0.0 0.0 0.0 1.0"/>
</material>

<material name="blue">
  <color rgba="0.0 0.0 0.8 1.0"/>
</material>

<material name="green">
  <color rgba="0.0 0.8 0.0 1.0"/>
</material>

<material name="grey">
  <color rgba="0.2 0.2 0.2 1.0"/>
</material>

<material name="orange">
  <color rgba="${255/255} ${108/255} ${10/255} 1.0"/>
</material>

<material name="brown">
  <color rgba="${222/255} ${207/255} ${195/255} 1.0"/>
</material>

<material name="red">
  <color rgba="0.8 0.0 0.0 1.0"/>
</material>

<material name="white">
  <color rgba="1.0 1.0 1.0 1.0"/>
</material>



  <!-- Add chassis and it's inertia link -->

  <link name="base_link" />

  <link name="chassis">
    <visual>
        <origin xyz="0 0 0" rpy="0 0 0" />
        <geometry>
            <mesh filename="package://f1tenth_description/meshes/chassis.STL" />
        </geometry>
      <material name="red" />
    </visual>
    <inertial>
        <origin xyz="0.1477 0 0" rpy="0 0 0" />
        <mass value="4.0" />
        <inertia ixx="0.010609" ixy="0"         ixz="0"
                                iyy="0.050409"  iyz="0"
                                                izz="0.05865" />
    </inertial>
    <collision>
        <origin xyz="0 0 0" rpy="0 0 0" />
        <geometry>
            <mesh filename="package://f1tenth_description/meshes/chassis.STL" />
        </geometry>
    </collision>
  </link>

  <joint name="base_link_joint" type="fixed">
    <origin xyz="0 0 0.05" rpy="0 0 0" />
    <parent link="base_link" />
    <child link="chassis" />
  </joint>

  <!-- Add the left rear wheel with its joints and tranmissions -->

  <link name="left_rear_wheel">
    <inertial>
        <origin xyz="0 0 -0.0225" rpy="0 0 0" />
        <mass value="0.34055" />
        <inertia ixx="0.00026046"   ixy="0"          ixz="0"
                                    iyy="0.00026046" iyz="0"
                                    izz="0.00041226" />
    </inertial>
    <visual>
        <origin xyz="0 0 0" rpy="0 0 0" />
        <geometry>
            <mesh filename="package://f1tenth_description/meshes/left_rear_wheel.STL" />
        </geometry>
        <material name="black" />
    </visual>
    <collision>
        <origin xyz="0 0 -0.0225" rpy="0 0 0" />
        <geometry>
            <cylinder length="0.045" radius="0.05" />
        </geometry>
    </collision>
  </link>

  <joint name="left_rear_wheel_joint" type="continuous">
    <origin xyz="0 0.1 0" rpy="1.5708 0 0" />
    <parent link="chassis" />
    <child link="left_rear_wheel" />
    <axis xyz="0 0 -1" />
    <limit effort="10" velocity="100" />
  </joint>

  <transmission name="left_rear_wheel_transmission" type="SimpleTransmission">
    <type>transmission_interface/SimpleTransmission</type>
    <joint name="left_rear_wheel_joint">
      <hardwareInterface>hardware_interface/EffortJointInterface</hardwareInterface>
    </joint>
    <actuator name="left_rear_wheel_motor">
      <hardwareInterface>hardware_interface/EffortJointInterface</hardwareInterface>
      <mechanicalReduction>1</mechanicalReduction>
    </actuator>
  </transmission>

  <!-- Add the right rear wheel with its joints and tranmissions -->

  <link name="right_rear_wheel">
    <inertial>
        <origin xyz="0 0 0.0225" rpy="0 0 0" />
        <mass value="0.34055" />
        <inertia ixx="0.00026046"   ixy="0"          ixz="0"
                                    iyy="0.00026046" iyz="0"
                                    izz="0.00041226" />
    </inertial>
    <visual>
        <origin xyz="0 0 0" rpy="0 0 0" />
        <geometry>
            <mesh filename="package://f1tenth_description/meshes/right_rear_wheel.STL" />
        </geometry>
        <material name="black" />
    </visual>
    <collision>
        <origin xyz="0 0 0.0225" rpy="0 0 0" />
        <geometry>
            <cylinder length="0.045" radius="0.05" />
        </geometry>
    </collision>
  </link>

  <joint name="right_rear_wheel_joint" type="continuous">
    <origin xyz="0 -0.1 0" rpy="1.5708 0 0" />
    <parent link="chassis" />
    <child link="right_rear_wheel" />
    <axis xyz="0 0 -1" />
    <limit effort="10" velocity="100" />
  </joint>

  <transmission name="right_rear_wheel_transmission" type="SimpleTransmission">
    <type>transmission_interface/SimpleTransmission</type>
    <joint name="right_rear_wheel_joint">
      <hardwareInterface>hardware_interface/EffortJointInterface</hardwareInterface>
    </joint>
    <actuator name="right_rear_wheel_motor">
      <hardwareInterface>hardware_interface/EffortJointInterface</hardwareInterface>
      <mechanicalReduction>1</mechanicalReduction>
    </actuator>
  </transmission>

  <!-- Add the left steering hinge with its joints and tranmissions -->

  <link name="left_steering_hinge">
    <inertial>
        <origin xyz="0 0 0" rpy="0 0 0" />
        <mass value="0.100" />
        <inertia ixx="4E-06"    ixy="0"      ixz="0"
                                iyy="4E-06"  iyz="0"
                                izz="4E-06" />
    </inertial>
    <visual>
        <origin xyz="0 0 0" rpy="0 0 0" />
        <geometry>
            <mesh filename="package://f1tenth_description/meshes/left_steering_hinge.STL" />
        </geometry>
        <material name="grey" />
    </visual>
    <collision>
        <origin xyz="0 0 0" rpy="0 0 0" />
        <geometry>
            <mesh filename="package://f1tenth_description/meshes/left_steering_hinge.STL" />
        </geometry>
    </collision>
  </link>

  <joint name="left_steering_hinge_joint" type="revolute">
    <origin xyz="0.325 0.1 0" rpy="0 1.5708 0" />
    <parent link="chassis" />
    <child link="left_steering_hinge" />
    <axis xyz="-1 0 0" />
    <limit lower="-1.0" upper="1.0" effort="10" velocity="100" />
  </joint>

  <transmission name="left_steering_hinge_transmission" type="SimpleTransmission">
    <type>transmission_interface/SimpleTransmission</type>
    <joint name="left_steering_hinge_joint">
      <hardwareInterface>hardware_interface/EffortJointInterface</hardwareInterface>
    </joint>
    <actuator name="left_steering_hinge_motor">
      <hardwareInterface>hardware_interface/EffortJointInterface</hardwareInterface>
      <mechanicalReduction>1</mechanicalReduction>
    </actuator>
  </transmission>

  <!-- Add the right steering hinge with its joints and tranmissions -->

  <link name="right_steering_hinge">
    <inertial>
        <origin xyz="0 0 0" rpy="0 0 0" />
        <mass value="0.100" />
        <inertia ixx="4E-06"    ixy="0"      ixz="0"
                                iyy="4E-06"  iyz="0"
                                izz="4E-06" />
    </inertial>
    <visual>
        <origin xyz="0 0 0" rpy="0 0 0" />
        <geometry>
            <mesh filename="package://f1tenth_description/meshes/left_steering_hinge.STL" />
        </geometry>
        <material name="grey" />
    </visual>
    <collision>
        <origin xyz="0 0 0" rpy="0 0 0" />
        <geometry>
            <mesh filename="package://f1tenth_description/meshes/left_steering_hinge.STL" />
        </geometry>
    </collision>
  </link>

  <joint name="right_steering_hinge_joint" type="revolute">
    <origin xyz="0.325 -0.1 0" rpy="0 1.5708 0" />
    <parent link="chassis" />
    <child link="right_steering_hinge" />
    <axis xyz="-1 0 0" />
    <limit lower="-1.0" upper="1.0" effort="10" velocity="100" />
  </joint>

  <transmission name="right_steering_hinge_transmission" type="SimpleTransmission">
    <type>transmission_interface/SimpleTransmission</type>
    <joint name="right_steering_hinge_joint">
      <hardwareInterface>hardware_interface/EffortJointInterface</hardwareInterface>
    </joint>
    <actuator name="right_steering_hinge_motor">
      <hardwareInterface>hardware_interface/EffortJointInterface</hardwareInterface>
      <mechanicalReduction>1</mechanicalReduction>
    </actuator>
  </transmission>

  <!-- Add the left front wheel with its joints and tranmissions -->

  <link name="left_front_wheel">
    <inertial>
        <origin xyz="0 0 -0.0225" rpy="0 0 0" />
        <mass value="0.34055" />
        <inertia ixx="0.00026046" ixy="0"          ixz="0"
                            iyy="0.00026046" iyz="0"
                                             izz="0.00041226" />
    </inertial>
    <visual>
        <origin xyz="0 0 0" rpy="0 0 0" />
        <geometry>
            <mesh filename="package://f1tenth_description/meshes/left_front_wheel.STL" />
        </geometry>
        <material name="black" />
    </visual>
    <collision>
        <origin xyz="0 0 -0.0225" rpy="0 0 0" />
        <geometry>
            <cylinder length="0.045" radius="0.05" />
        </geometry>
    </collision>
  </link>

  <joint name="left_front_wheel_joint" type="continuous">
    <origin xyz="0 0 0" rpy="1.5708 0 0" />
    <parent link="left_steering_hinge" />
    <child link="left_front_wheel" />
    <axis xyz="0 0 -1" />
    <limit effort="10" velocity="100" />
  </joint>

  <transmission name="left_front_wheel_transmission" type="SimpleTransmission">
    <type>transmission_interface/SimpleTransmission</type>
    <joint name="left_front_wheel_joint">
      <hardwareInterface>hardware_interface/EffortJointInterface</hardwareInterface>
    </joint>
    <actuator name="left_front_wheel_motor">
      <hardwareInterface>hardware_interface/EffortJointInterface</hardwareInterface>
      <mechanicalReduction>1</mechanicalReduction>
    </actuator>
  </transmission>

  <!-- Add the left front wheel with its joints and tranmissions -->

  <link name="right_front_wheel">
    <inertial>
        <origin xyz="0 0 0.0225" rpy="0 0 0" />
        <mass value="0.34055" />
        <inertia ixx="0.00026046" ixy="0"          ixz="0"
                            iyy="0.00026046" iyz="0"
                                             izz="0.00041226" />
    </inertial>
    <visual>
        <origin xyz="0 0 0" rpy="0 0 0" />
        <geometry>
            <mesh filename="package://f1tenth_description/meshes/right_front_wheel.STL" />
        </geometry>
        <material name="black" />
    </visual>
    <collision>
        <origin xyz="0 0 0.0225" rpy="0 0 0" />
        <geometry>
            <cylinder length="0.045" radius="0.05" />
        </geometry>
    </collision>
  </link>

  <joint name="right_front_wheel_joint" type="continuous">
    <origin xyz="0 0 0" rpy="1.5708 0 0" />
    <parent link="right_steering_hinge" />
    <child link="right_front_wheel" />
    <axis xyz="0 0 -1" />
    <limit effort="10" velocity="100"/>
  </joint>
  
  <transmission name="right_front_wheel_transmission" type="SimpleTransmission">
    <type>transmission_interface/SimpleTransmission</type>
    <joint name="right_front_wheel_joint">
      <hardwareInterface>hardware_interface/EffortJointInterface</hardwareInterface>
    </joint>
    <actuator name="right_front_wheel_motor">
      <hardwareInterface>hardware_interface/EffortJointInterface</hardwareInterface>
      <mechanicalReduction>1</mechanicalReduction>
    </actuator>
  </transmission>

  <!-- Add Hokuyo laser scanner -->

  <link name="laser">
    <inertial>
        <origin xyz="0 0 0" rpy="0 0 0" />
        <mass value="0.130" />
        <inertia ixx="4E-06" ixy="0"           ixz="0"
                            iyy="4E-06"  iyz="0"
                                              izz="4E-06" />
    </inertial>
    <collision>
      <origin xyz="0 0 0" rpy="0 0 0"/>
      <geometry>
        <box size="0.1 0.1 0.1"/>
      </geometry>
    </collision>
    <visual>
      <origin xyz="0 0 0" rpy="0 0 0"/>
      <geometry>
        <mesh filename="package://f1tenth_description/meshes/hokuyo.dae"/>
        <material name="grey" />
      </geometry>
    </visual>
  </link>

  <joint name="hokuyo_joint" type="fixed">
    <origin xyz="0.33 0.0 0.065" rpy="0 0 0"/>
    <parent link="chassis" />
    <child link="laser" />
    <axis xyz="0 0 1" />
  </joint>

<!-- Add IMU sensor -->

<link name="imuSensor">
  <inertial>
        <origin xyz="0 0 0" rpy="0 0 0" />
        <mass value="0.005" />
        <inertia ixx="4E-06" ixy="0"           ixz="0"
                            iyy="4E-06"  iyz="0"
                                              izz="4E-06" />
    </inertial>
    <collision>
      <origin xyz="0 0 0" rpy="0 0 0"/>
      <geometry>
        <box size="0.015 0.015 0.005"/>
      </geometry>
    </collision>
    <visual>
      <origin xyz="0 0 0" rpy="0 0 0"/>
      <geometry>
        <box size="0.015 0.015 0.005"/>
      </geometry>
      <material name="grey" />
    </visual>
</link>

<joint name="imu_joint" type="fixed">
  <origin xyz="0.28 0.0 0.035" rpy="0 0 0"/>
  <parent link="chassis"/>
  <child link="imuSensor"/>
  <axis xyz="0 0 1"/>
</joint>


<!-- Gazebo references -->

<gazebo reference="chassis">
  <mu1 value="0.0"/>
  <mu2 value="0.0"/>
  <kp  value="10000000.0" />
  <kd  value="1.0" />
  <material>Gazebo/Red</material>
</gazebo>

<gazebo reference="left_rear_wheel">
  <mu1 value="1.0"/>
  <mu2 value="1.0"/>
  <kp  value="10000000.0" />
  <kd  value="1.0" />
  <fdir1 value="1 0 0"/>
  <material>Gazebo/Black</material>
</gazebo>

<gazebo reference="right_rear_wheel">
  <mu1 value="1.0"/>
  <mu2 value="1.0"/>
  <kp  value="10000000.0" />
  <kd  value="1.0" />
  <fdir1 value="1 0 0"/>
  <material>Gazebo/Black</material>
</gazebo>

<gazebo reference="left_front_wheel">
  <mu1 value="1.0"/>
  <mu2 value="1.0"/>
  <kp  value="10000000.0" />
  <kd  value="1.0" />
  <fdir1 value="0 0 1"/>
  <material>Gazebo/Black</material>
</gazebo>

<gazebo reference="right_front_wheel">
  <mu1 value="1.0"/>
  <mu2 value="1.0"/>
  <kp  value="10000000.0" />
  <kd  value="1.0" />
  <fdir1 value="0 0 1"/>
  <material>Gazebo/Black</material>
</gazebo>


  <!-- hokuyo -->

<gazebo reference="laser">
    <material>Gazebo/Grey</material>
    <sensor type="ray" name="hokuyo_sensor">
      <pose>0 0 0.0124 0 0 0</pose>
      <visualize>true</visualize>
      <update_rate>40</update_rate>
      <ray>
        <scan>
          <horizontal>
            <samples>1081</samples>
            <resolution>1</resolution>
            <min_angle>-2.3561944902</min_angle>
            <max_angle>2.3561944902</max_angle>
          </horizontal>
        </scan>
        <range>
          <min>0.1</min>
          <max>10.0</max>
          <resolution>0.01</resolution>
        </range>
        <noise>
          <type>gaussian</type>
          <mean>0.0</mean>
          <stddev>0.01</stddev>
        </noise>
      </ray>
      <plugin name="gazebo_ros_hokuyo_controller" filename="libgazebo_ros_laser.so">
        <topicName>/scan</topicName>
        <frameName>laser</frameName>
      </plugin>
    </sensor>
  </gazebo>

<!-- IMU Sensor -->
<gazebo reference="imuSensor">
    <gravity>true</gravity>
    <material>Gazebo/Grey</material>
    <sensor name="imu_sensor" type="imu">
      <always_on>true</always_on>
      <update_rate>100</update_rate>
      <visualize>true</visualize>
      <topic>/imu_data</topic>
      <plugin filename="libgazebo_ros_imu_sensor.so" name="imu_plugin">
        <topicName>/imu</topicName>
        <bodyName>imuSensor</bodyName>
        <updateRateHZ>8.0</updateRateHZ>
        <gaussianNoise>0.0</gaussianNoise>
        <xyzOffset>0 0 0</xyzOffset>
        <rpyOffset>0 0 0</rpyOffset>
        <frameName>imuSensor</frameName>
      </plugin>
      <pose>0 0 0 0 0 0</pose>
    </sensor>
  </gazebo>



  <!--Gazebo_ros_control plugin-->
<gazebo>
  <plugin name="gazebo_ros_control" filename="libgazebo_ros_control.so">
    <robotNamespace>/racecar</robotNamespace>
  </plugin>
</gazebo>

</robot>